<?xml version="1.0" ?>
<!-- =================================================================================== -->
<!-- |    This document was autogenerated by xacro from use_case_setup_iiwa.urdf.xacro | -->
<!-- |    EDITING THIS FILE BY HAND IS NOT RECOMMENDED                                 | -->
<!-- =================================================================================== -->
<robot name="iiwa_setup">
  <!-- Fix robot to world-->
  <link name="world"/>
  <!-- ************ ROBOT AND BASE **********     -->
  <!-- Create the torso link -->
  <joint name="right_torso_joint" type="fixed">
    <origin rpy="0 0 -1.5708" xyz="0 0 0.4"/>
    <parent link="world"/>
    <child link="right_torso_link"/>
  </joint>
  <link name="right_torso_link">
    <visual>
      <origin rpy="0 0 0" xyz="0 0 0"/>
      <!-- <geometry>
            <mesh filename="package://cable_controller/robot_description/meshes/torso.stl" scale="0.001 0.001 0.001"/>
        </geometry> -->
      <material name="White"/>
    </visual>
  </link>
  <!-- <joint name="${prefix_left}torso_joint" type="fixed">
      <parent link="world"/>
      <origin xyz="0 0 0.4" rpy="0 0 -1.5708"/>
      <child link="${prefix_left}torso_link"/>
    </joint> -->
  <!-- <link name="${prefix_left}torso_link">
    </link> -->
  <!-- <xacro:iiwa prefix="${prefix_left}" parent="${prefix_left}torso_link">
        <origin xyz="-0.11127 0.0 -0.07513" rpy="-0.785398 0.0  1.5708"/>
    </xacro:iiwa> -->
  <material name="gray">
    <color rgba="0.5 0.5 0.5 1.0"/>
  </material>
  <link name="right_iiwa_base" type="fixed"/>
  <joint name="right_iiwa_root_joint" type="fixed">
    <origin rpy="0.785398 0.0  1.5708" xyz="0.11127 0.0 -0.07513"/>
    <parent link="world"/>
    <child link="right_iiwa_base"/>
  </joint>
  <joint name="right_iiwa_base_joint" type="fixed">
    <origin rpy="0.0 0 0" xyz="0 0 0"/>
    <parent link="right_iiwa_base"/>
    <child link="right_link_0"/>
  </joint>
  <link name="right_link_0">
    <visual>
      <origin rpy="0.0 0 0" xyz="0 0 0"/>
      <geometry>
        <mesh filename="package://iiwa_description/meshes/lbr_iiwa_14_r820/visual/base_link.dae"/>
      </geometry>
    </visual>
    <collision>
      <origin rpy="0 0 0" xyz="0 0 0"/>
      <geometry>
        <mesh filename="package://iiwa_description/meshes/lbr_iiwa_14_r820/collision/base_link.stl"/>
      </geometry>
    </collision>
    <inertial>
      <origin rpy="0 0 0" xyz="-0.1 0 0.07"/>
      <mass value="5"/>
      <inertia ixx="0.05" ixy="0" ixz="0" iyy="0.06" iyz="0" izz="0.03"/>
    </inertial>
  </link>
  <link name="right_link_1">
    <visual>
      <origin rpy="0 0 0" xyz="0 0 0"/>
      <geometry>
        <mesh filename="package://iiwa_description/meshes/lbr_iiwa_14_r820/visual/link_1.dae"/>
      </geometry>
    </visual>
    <collision>
      <origin rpy="0 0 0" xyz="0 0 0"/>
      <geometry>
        <mesh filename="package://iiwa_description/meshes/lbr_iiwa_14_r820/collision/link_1.stl"/>
      </geometry>
    </collision>
    <inertial>
      <origin rpy="0 0 0" xyz="0 -0.03 0.12"/>
      <mass value="4"/>
      <inertia ixx="0.1" ixy="0" ixz="0" iyy="0.09" iyz="0" izz="0.02"/>
    </inertial>
  </link>
  <link name="right_link_2">
    <visual>
      <origin rpy="0 0 0" xyz="0 0 0"/>
      <geometry>
        <mesh filename="package://iiwa_description/meshes/lbr_iiwa_14_r820/visual/link_2.dae"/>
      </geometry>
    </visual>
    <collision>
      <origin rpy="0 0 0" xyz="0 0 0"/>
      <geometry>
        <mesh filename="package://iiwa_description/meshes/lbr_iiwa_14_r820/collision/link_2.stl"/>
      </geometry>
    </collision>
    <inertial>
      <origin rpy="0 0 0" xyz="0.0003 0.059 0.042"/>
      <mass value="4"/>
      <inertia ixx="0.05" ixy="0" ixz="0" iyy="0.018" iyz="0" izz="0.044"/>
    </inertial>
  </link>
  <link name="right_link_3">
    <visual>
      <origin rpy="0 0 0" xyz="0 0 0"/>
      <geometry>
        <mesh filename="package://iiwa_description/meshes/lbr_iiwa_14_r820/visual/link_3.dae"/>
      </geometry>
    </visual>
    <collision>
      <origin rpy="0 0 0" xyz="0 0 0"/>
      <geometry>
        <mesh filename="package://iiwa_description/meshes/lbr_iiwa_14_r820/collision/link_3.stl"/>
      </geometry>
    </collision>
    <inertial>
      <origin rpy="0 0 0" xyz="0 0.03 0.13"/>
      <mass value="3"/>
      <inertia ixx="0.08" ixy="0" ixz="0" iyy="0.075" iyz="0" izz="0.01"/>
    </inertial>
  </link>
  <link name="right_link_4">
    <visual>
      <origin rpy="0 0 0" xyz="0 0 0"/>
      <geometry>
        <mesh filename="package://iiwa_description/meshes/lbr_iiwa_14_r820/visual/link_4.dae"/>
      </geometry>
    </visual>
    <collision>
      <origin rpy="0 0 0" xyz="0 0 0"/>
      <geometry>
        <mesh filename="package://iiwa_description/meshes/lbr_iiwa_14_r820/collision/link_4.stl"/>
      </geometry>
    </collision>
    <inertial>
      <origin rpy="0 0 0" xyz="0 0.067 0.034"/>
      <mass value="2.7"/>
      <inertia ixx="0.03" ixy="0" ixz="0" iyy="0.01" iyz="0" izz="0.029"/>
    </inertial>
  </link>
  <link name="right_link_5">
    <visual>
      <origin rpy="0 0 0" xyz="0 0 0"/>
      <geometry>
        <mesh filename="package://iiwa_description/meshes/lbr_iiwa_14_r820/visual/link_5.dae"/>
      </geometry>
    </visual>
    <collision>
      <origin rpy="0 0 0" xyz="0 0 0"/>
      <geometry>
        <mesh filename="package://iiwa_description/meshes/lbr_iiwa_14_r820/collision/link_5.stl"/>
      </geometry>
    </collision>
    <inertial>
      <origin rpy="0 0 0" xyz="0.0001 0.021 0.076"/>
      <mass value="1.7"/>
      <inertia ixx="0.02" ixy="0" ixz="0" iyy="0.018" iyz="0" izz="0.005"/>
    </inertial>
  </link>
  <link name="right_link_6">
    <visual>
      <origin rpy="0 0 0" xyz="0 0 0"/>
      <geometry>
        <mesh filename="package://iiwa_description/meshes/lbr_iiwa_14_r820/visual/link_6.dae"/>
      </geometry>
    </visual>
    <collision>
      <origin rpy="0 0 0" xyz="0 0 0"/>
      <geometry>
        <mesh filename="package://iiwa_description/meshes/lbr_iiwa_14_r820/collision/link_6.stl"/>
      </geometry>
    </collision>
    <inertial>
      <origin rpy="0 0 0" xyz="0 0.0006 0.0004"/>
      <mass value="1.8"/>
      <inertia ixx="0.025" ixy="0" ixz="0" iyy="0.0136" iyz="0" izz="0.0247"/>
    </inertial>
  </link>
  <link name="right_link_7">
    <visual>
      <origin rpy="0 0 0" xyz="0 0 0.07"/>
      <material name="gray"/>
      <geometry>
        <mesh filename="package://iiwa_description/meshes/lbr_iiwa_14_r820/visual/link_7_2.stl" scale="0.001 0.001 0.001"/>
      </geometry>
    </visual>
    <collision>
      <origin rpy="0 0 0" xyz="0 0 0.07"/>
      <geometry>
        <mesh filename="package://iiwa_description/meshes/lbr_iiwa_14_r820/collision/link_7_2.stl" scale="0.001 0.001 0.001"/>
      </geometry>
    </collision>
    <inertial>
      <origin rpy="0 0 0" xyz="0 0 0.02"/>
      <mass value="0.42857142857142855"/>
      <!--this is for the MFT Pneumatisch flange-->
      <inertia ixx="0.01" ixy="0" ixz="0" iyy="0.01" iyz="0" izz="0.01"/>
    </inertial>
  </link>
  <link name="right_tool0"/>
  <joint name="right_joint_a1" type="revolute">
    <origin rpy="0 0 0" xyz="0 0 0"/>
    <parent link="right_link_0"/>
    <child link="right_link_1"/>
    <axis xyz="0 0 1"/>
    <limit effort="320" lower="-2.9668" upper="2.9668" velocity="1.4834"/>
  </joint>
  <joint name="right_joint_a2" type="revolute">
    <origin rpy="0 0 0" xyz="-0.00043624 0 0.36"/>
    <parent link="right_link_1"/>
    <child link="right_link_2"/>
    <axis xyz="0 1 0"/>
    <limit effort="320" lower="-2.0942" upper="2.0942" velocity="1.4834"/>
  </joint>
  <joint name="right_joint_a3" type="revolute">
    <origin rpy="0 0 0" xyz="0 0 0"/>
    <parent link="right_link_2"/>
    <child link="right_link_3"/>
    <axis xyz="0 0 1"/>
    <limit effort="176" lower="-2.9668" upper="2.9668" velocity="1.7452"/>
  </joint>
  <joint name="right_joint_a4" type="revolute">
    <origin rpy="0 0 0" xyz="0.00043624 0 0.42"/>
    <parent link="right_link_3"/>
    <child link="right_link_4"/>
    <axis xyz="0 -1 0"/>
    <limit effort="176" lower="-2.0942" upper="2.0942" velocity="1.3089"/>
  </joint>
  <joint name="right_joint_a5" type="revolute">
    <origin rpy="0 0 0" xyz="0 0 0"/>
    <parent link="right_link_4"/>
    <child link="right_link_5"/>
    <axis xyz="0 0 1"/>
    <limit effort="110" lower="-2.9668" upper="2.9668" velocity="2.2688"/>
  </joint>
  <joint name="right_joint_a6" type="revolute">
    <origin rpy="0 0 0" xyz="0 0 0.4"/>
    <parent link="right_link_5"/>
    <child link="right_link_6"/>
    <axis xyz="0 1 0"/>
    <limit effort="40" lower="-2.0942" upper="2.0942" velocity="2.356"/>
  </joint>
  <joint name="right_joint_a7" type="revolute">
    <origin rpy="0 0 0" xyz="0 0 0"/>
    <parent link="right_link_6"/>
    <child link="right_link_7"/>
    <axis xyz="0 0 1"/>
    <limit effort="40" lower="-3.0541" upper="3.0541" velocity="2.356"/>
  </joint>
  <joint name="right_joint_a7-tool0" type="fixed">
    <origin rpy="0 0 0" xyz="0 0 0.154"/>
    <parent link="right_link_7"/>
    <child link="right_tool0"/>
    <axis xyz="0 0 0"/>
  </joint>
  <!-- LEFT FRAMES -->
  <!-- <link name="${prefix_left}ft_sensor_frame"/>
  	<joint name="${prefix_left}ft_sensor_joint" type="fixed">
  		<origin xyz="0 0 ${0.01 + 0.025/2}" rpy="${0} ${3.1416} ${-3.1416/4}"/>
  		<parent link="${prefix_left}tool0"/>
  		<child link="${prefix_left}ft_sensor_frame"/>
  	</joint> -->
  <!-- <link name="${prefix_left}gripper"/>
  	<joint name="${prefix_left}gripper_joint" type="fixed">
  		<origin xyz="0.0 0.0 0.19" rpy="${0} ${3.1416} 0"/>
  		<parent link="${prefix_left}tool0"/>
  		<child link="${prefix_left}gripper"/>
    </joint> -->
  <!-- RIGHT FRAMES -->
  <link name="right_ft_sensor_frame"/>
  <joint name="right_ft_sensor_joint" type="fixed">
    <origin rpy="0 0 3.1416" xyz="0 0 0.0225"/>
    <parent link="right_tool0"/>
    <child link="right_ft_sensor_frame"/>
  </joint>
  <link name="right_gripper"/>
  <joint name="right_gripper_joint" type="fixed">
    <origin rpy="0 3.1416 -1.5708" xyz="0.0 0.0 0.19"/>
    <parent link="right_tool0"/>
    <child link="right_gripper"/>
  </joint>
  <!-- combined scene -->
  <!-- <link name="tool_frame"/> -->
  <!-- <joint name="tool_frame_joint" type="fixed">
		<origin xyz="${x_w} ${y_w} ${z_w}" rpy="${roll_w} ${pitch_w} ${yaw_w}"/>
		<parent link="${prefix_left}ft_sensor_frame"/>
		<child link="tool_frame"/>
	</joint> -->
</robot>
